Traceback (most recent call last):
  File "/home/runner/.cache/pypoetry/virtualenvs/ccs-MagXi3_o-py3.9/lib/python3.9/site-packages/jupyter_cache/executors/utils.py", line 58, in single_nb_execution
    executenb(
  File "/home/runner/.cache/pypoetry/virtualenvs/ccs-MagXi3_o-py3.9/lib/python3.9/site-packages/nbclient/client.py", line 1204, in execute
    return NotebookClient(nb=nb, resources=resources, km=km, **kwargs).execute()
  File "/home/runner/.cache/pypoetry/virtualenvs/ccs-MagXi3_o-py3.9/lib/python3.9/site-packages/nbclient/util.py", line 84, in wrapped
    return just_run(coro(*args, **kwargs))
  File "/home/runner/.cache/pypoetry/virtualenvs/ccs-MagXi3_o-py3.9/lib/python3.9/site-packages/nbclient/util.py", line 62, in just_run
    return loop.run_until_complete(coro)
  File "/opt/hostedtoolcache/Python/3.9.15/x64/lib/python3.9/asyncio/base_events.py", line 647, in run_until_complete
    return future.result()
  File "/home/runner/.cache/pypoetry/virtualenvs/ccs-MagXi3_o-py3.9/lib/python3.9/site-packages/nbclient/client.py", line 663, in async_execute
    await self.async_execute_cell(
  File "/home/runner/.cache/pypoetry/virtualenvs/ccs-MagXi3_o-py3.9/lib/python3.9/site-packages/nbclient/client.py", line 965, in async_execute_cell
    await self._check_raise_for_error(cell, cell_index, exec_reply)
  File "/home/runner/.cache/pypoetry/virtualenvs/ccs-MagXi3_o-py3.9/lib/python3.9/site-packages/nbclient/client.py", line 862, in _check_raise_for_error
    raise CellExecutionError.from_cell_and_msg(cell, exec_reply_content)
nbclient.exceptions.CellExecutionError: An error occurred while executing the following cell:
------------------
#Read Data

dbname_DFT='../DFT_DB.db'
dbname_CCS='CCS_DB.db'
db_ccs=db.connect(dbname_CCS)
db_dft=db.connect(dbname_DFT)
epred=[];edft=[]; eccs=[];
for row in tqdm(db_dft.select(), total=len(db_dft)):
    structure=row.toatoms()
    natoms=len(structure.get_atomic_numbers())
    id=str(row.key)
    eccs.append(db_ccs.get('key='+id).energy/natoms)
    edft.append(db_dft.get('key='+id).energy/natoms) 

------------------

[0;31m---------------------------------------------------------------------------[0m
[0;31mAttributeError[0m                            Traceback (most recent call last)
Cell [0;32mIn [6], line 12[0m
[1;32m     10[0m natoms[38;5;241m=[39m[38;5;28mlen[39m(structure[38;5;241m.[39mget_atomic_numbers())
[1;32m     11[0m [38;5;28mid[39m[38;5;241m=[39m[38;5;28mstr[39m(row[38;5;241m.[39mkey)
[0;32m---> 12[0m eccs[38;5;241m.[39mappend([43mdb_ccs[49m[38;5;241;43m.[39;49m[43mget[49m[43m([49m[38;5;124;43m'[39;49m[38;5;124;43mkey=[39;49m[38;5;124;43m'[39;49m[38;5;241;43m+[39;49m[38;5;28;43mid[39;49m[43m)[49m[38;5;241;43m.[39;49m[43menergy[49m[38;5;241m/[39mnatoms)
[1;32m     13[0m edft[38;5;241m.[39mappend(db_dft[38;5;241m.[39mget([38;5;124m'[39m[38;5;124mkey=[39m[38;5;124m'[39m[38;5;241m+[39m[38;5;28mid[39m)[38;5;241m.[39menergy[38;5;241m/[39mnatoms)

[0;31mAttributeError[0m: 'AtomsRow' object has no attribute 'energy'
AttributeError: 'AtomsRow' object has no attribute 'energy'

